Workbook
Name A: #REF!
Name CeCos: [1]CECOS!$A$21:$B$41
Name PROVEEDOR: #REF!
Name TESA: #REF!

Sheet MasivoRebate SD
A1: ID CABC(1) | B1: Fecha Doc | C1: Texto Cab Doc | D1: REFERENCIA | E1: ID POSC(2)Acreedor | F1: RUC | G1: Cond Pago | H1: Ind Impto | I1: Tipo Detr | J1: Ind Detra | K1: Asignación | L1: Texto Posición | M1: ID POSC(2) Cuenta GASTO | N1: Cuenta Gasto | O1: DETALLE | P1: Centro Costo | Q1: Importe MD | R1: Ind Impto | S1: Asignación | T1: Texto Posición | U1: N° OC
A2: 1 | B2: 31.07.2026 | D2: 01-0F001-0056835 | E2: 2 | F2: 20601233488 | G2: CP02 | H2: C1 | L2: RBT-NO DEVOLUCION1.000-PASADOS 15 DIAS DESDE LA RECEPCIÓN DEL PRESENTE DOCUMENTO SIN FORMULARSE RECLAMO ALGUNO LO DAREMOS POR ACEPTADO JULIO 2026 | M2: 2 | N2: 6371100005 | O2: =+_xlfn.XLOOKUP(N2,Hoja2!B:B,Hoja2!C:C,,0) | P2: 1030210002 | Q2: 169.85 | R2: C1 | T2: RBT-NO DEVOLUCION1.000-PASADOS 15 DIAS DESDE LA RECEPCIÓN DEL PRESENTE DOCUMENTO SIN FORMULARSE RECLAMO ALGUNO LO DAREMOS POR ACEPTADO JULIO 2026
A3: =+A2+1 | B3: 06.08.2026 | D3: 01-0FA39-0027008 | E3: 2 | F3: 20109072177 | G3: CP02 | H3: C1 | L3: RBT-PROMOCIONES DIVERSAS EC - M001 PROMOCION E COMMERCE JULIO 2026 | M3: 2 | N3: 6371100002 | O3: =+_xlfn.XLOOKUP(N3,Hoja2!B:B,Hoja2!C:C,,0) | P3: 1030210005 | Q3: 115.64 | R3: C1 | T3: RBT-PROMOCIONES DIVERSAS EC - M001 PROMOCION E COMMERCE JULIO 2026
A4: =+A3+1 | B4: 06.08.2026 | D4: 01-0FA38-0673417 | E4: 2 | F4: 20109072177 | G4: CP02 | H4: C1 | L4: RBT-PROMOCIONES DIVERSAS - M001 JULIO 2026 | M4: 2 | N4: 6371100002 | O4: =+_xlfn.XLOOKUP(N4,Hoja2!B:B,Hoja2!C:C,,0) | P4: 1030210005 | Q4: 160.35 | R4: C1 | T4: RBT-PROMOCIONES DIVERSAS - M001 JULIO 2026
A5: =+A4+1 | B5: 10.08.2026 | D5: 01-0FF32-0544937 | E5: 2 | F5: 20508565934 | G5: CP02 | H5: C1 | L5: RBT-SER EVAL JULIO 2026 | M5: 2 | N5: 6371100007 | O5: =+_xlfn.XLOOKUP(N5,Hoja2!B:B,Hoja2!C:C,,0) | P5: 1030210003 | Q5: 47.2 | R5: C1 | T5: RBT-SER EVAL JULIO 2026
A6: =+A5+1 | B6: 10.08.2026 | D6: 01-0FF32-0544664 | E6: 2 | F6: 20508565934 | G6: CP02 | H6: C1 | L6: RBT-SO 2DO 50 CMR 13 JUL 2026 | M6: 2 | N6: 6371100002 | O6: =+_xlfn.XLOOKUP(N6,Hoja2!B:B,Hoja2!C:C,,0) | P6: 1030210003 | Q6: 439.44 | R6: C1 | T6: RBT-SO 2DO 50 CMR 13 JUL 2026
A7: =+A6+1 | B7: 10.08.2026 | D7: 01-0FF32-0544668 | E7: 2 | F7: 20508565934 | G7: CP02 | H7: C1 | L7: RBT-VENTA NOCTURNA LA CALERA TOTTUS ECOM FLC JULIO 2026 | M7: 2 | N7: 6371100002 | O7: =+_xlfn.XLOOKUP(N7,Hoja2!B:B,Hoja2!C:C,,0) | P7: 1030210003 | Q7: 611.43 | R7: C1 | T7: RBT-VENTA NOCTURNA LA CALERA TOTTUS ECOM FLC JULIO 2026
A8: =+A7+1 | B8: 10.08.2026 | D8: 01-0FF32-0544661 | E8: 2 | F8: 20508565934 | G8: CP02 | H8: C1 | L8: RBT-SO 2DO 50 CMR 27 JUL 2026 | M8: 2 | N8: 6371100002 | O8: =+_xlfn.XLOOKUP(N8,Hoja2!B:B,Hoja2!C:C,,0) | P8: 1030210003 | Q8: 527.83 | R8: C1 | T8: RBT-SO 2DO 50 CMR 27 JUL 2026
A9: =+A8+1 | B9: 10.08.2026 | D9: 01-0FF32-0544660 | E9: 2 | F9: 20508565934 | G9: CP02 | H9: C1 | L9: RBT-SO 2DO 50 CMR 20 JUL 2026 | M9: 2 | N9: 6371100002 | O9: =+_xlfn.XLOOKUP(N9,Hoja2!B:B,Hoja2!C:C,,0) | P9: 1030210003 | Q9: 493.31 | R9: C1 | T9: RBT-SO 2DO 50 CMR 20 JUL 2026
A10: =+A9+1 | B10: 10.08.2026 | D10: 01-0FF32-0544310 | E10: 2 | F10: 20508565934 | G10: CP02 | H10: C1 | L10: RBT-HS15 LA CALERA TOTTUS ECOM FLC JULIO 2026 | M10: 2 | N10: 6371100002 | O10: =+_xlfn.XLOOKUP(N10,Hoja2!B:B,Hoja2!C:C,,0) | P10: 1030210003 | Q10: 134.58 | R10: C1 | T10: RBT-HS15 LA CALERA TOTTUS ECOM FLC JULIO 2026
A11: =+A10+1 | B11: 10.08.2026 | D11: 01-0FF01-0153894 | E11: 2 | F11: 20393864886 | G11: CP02 | H11: C0 | L11: RBT-SO CROSS LA CALERAX30 Y AGUA 25L HS14 20 JULIO 2026 | M11: 2 | N11: 6371100002 | O11: =+_xlfn.XLOOKUP(N11,Hoja2!B:B,Hoja2!C:C,,0) | P11: 1030210004 | Q11: 11.43 | R11: C0 | T11: RBT-SO CROSS LA CALERAX30 Y AGUA 25L HS14 20 JULIO 2026
A12: =+A11+1 | B12: 10.08.2026 | D12: 01-0FF01-0153895 | E12: 2 | F12: 20393864886 | G12: CP02 | H12: C0 | L12: RBT-SO CROSS LA CALERAX15 Y 2 ACEITES HS14 2 JULIO 2026 | M12: 2 | N12: 6371100002 | O12: =+_xlfn.XLOOKUP(N12,Hoja2!B:B,Hoja2!C:C,,0) | P12: 1030210004 | Q12: 28.68 | R12: C0 | T12: RBT-SO CROSS LA CALERAX15 Y 2 ACEITES HS14 2 JULIO 2026
A13: =+A12+1 | B13: 10.08.2026 | D13: 01-0FF01-0153887 | E13: 2 | F13: 20393864886 | G13: CP02 | H13: C0 | L13: RBT-SO HVO JUMB LA CALERA 23 AL 29 JUL 2026 | M13: 2 | N13: 6371100002 | O13: =+_xlfn.XLOOKUP(N13,Hoja2!B:B,Hoja2!C:C,,0) | P13: 1030210004 | Q13: 40.83 | R13: C0 | T13: RBT-SO HVO JUMB LA CALERA 23 AL 29 JUL 2026
A14: =+A13+1 | B14: 10.08.2026 | D14: 01-0FF01-0153885 | E14: 2 | F14: 20393864886 | G14: CP02 | H14: C0 | L14: RBT-SO 2DO 50 CMR 27 JUL 2026 | M14: 2 | N14: 6371100002 | O14: =+_xlfn.XLOOKUP(N14,Hoja2!B:B,Hoja2!C:C,,0) | P14: 1030210004 | Q14: 8.52 | R14: C0 | T14: RBT-SO 2DO 50 CMR 27 JUL 2026
... A24: =+A23+1 | B24: 20.08.2026 | D24: 01-0FF32-0548083 | E24: 2 | F24: 20508565934 | G24: CP02 | H24: C1 | L24: RBT-SO 2DO 50 CMR 10 AGOS 2026 | M24: 2 | N24: 6371100002 | O24: =+_xlfn.XLOOKUP(N24,Hoja2!B:B,Hoja2!C:C,,0) | P24: 1030210003 | Q24: 449.56 | R24: C1 | T24: RBT-SO 2DO 50 CMR 10 AGOS 2026
A25: =+A24+1 | B25: 31.05.2026 | C25: 02.06.2026 306305314 | D25: 01-0F020-0254594 | E25: 2 | F25: 20100070970 | G25: CP02 | H25: C1 | L25: RBT-INVERSION PUBLICITARIA.-RECO DIFERENCIA PESOS - 346837 MAYO 2026 | M25: 2 | N25: 6592100001 | O25: =+_xlfn.XLOOKUP(N25,Hoja2!B:B,Hoja2!C:C,,0) | P25: 1030210001 | Q25: 167560 | R25: C1 | T25: RBT-INVERSION PUBLICITARIA.-RECO DIFERENCIA PESOS - 346837 MAYO 2026
A26: =+A25+1 | B26: 31.05.2026 | C26: 03.06.2026 306467013 | D26: 01-0F020-0255504 | E26: 2 | F26: 20100070970 | G26: CP02 | H26: C1 | L26: RBT-INVERSION PUBLICITARIA.-DIF PESOS HUEVOS MASS 2 - 341067 MAYO 2026 | M26: 2 | N26: 6592100001 | O26: =+_xlfn.XLOOKUP(N26,Hoja2!B:B,Hoja2!C:C,,0) | P26: 1030210001 | Q26: 125080 | R26: C1 | T26: RBT-INVERSION PUBLICITARIA.-DIF PESOS HUEVOS MASS 2 - 341067 MAYO 2026
A27: =+A26+1 | B27: 01.07.2026 | C27: 10.08.2026 312579712 | D27: 01-0FA38-0662036 | E27: 2 | F27: 20109072177 | G27: CP02 | H27: C1 | L27: RBT-PROMOCIONES DIVERSAS EC - M001 JUNIO 2026 | M27: 2 | N27: 6371100002 | O27: =+_xlfn.XLOOKUP(N27,Hoja2!B:B,Hoja2!C:C,,0) | P27: 1030210005 | Q27: 9311.36 | R27: C1 | T27: RBT-PROMOCIONES DIVERSAS EC - M001 JUNIO 2026
A28: =+A27+1 | B28: 01.07.2026 | C28: 10.08.2026 312579713 | D28: 01-0FA38-0662037 | E28: 2 | F28: 20109072177 | G28: CP02 | H28: C1 | L28: RBT-PROMOCIONES DIVERSAS - M001 AVISO DESCUENTOMETRO 26.06 al 29.06 | M28: 2 | N28: 6371100002 | O28: =+_xlfn.XLOOKUP(N28,Hoja2!B:B,Hoja2!C:C,,0) | P28: 1030210005 | Q28: 768.33 | R28: C1 | T28: RBT-PROMOCIONES DIVERSAS - M001 AVISO DESCUENTOMETRO 26.06 al 29.06
A29: =+A28+1 | B29: 01.07.2026 | C29: 10.08.2026 312579711 | D29: 01-0FA38-0662035 | E29: 2 | F29: 20109072177 | G29: CP02 | H29: C1 | L29: RBT-PROMOCIONES DIVERSAS EC - M001 JUNIO 2026 | M29: 2 | N29: 6371100002 | O29: =+_xlfn.XLOOKUP(N29,Hoja2!B:B,Hoja2!C:C,,0) | P29: 1030210005 | Q29: 3229.74 | R29: C1 | T29: RBT-PROMOCIONES DIVERSAS EC - M001 JUNIO 2026
A30: =+A29+1 | B30: 30.06.2026 | C30: 02.07.2026 308874152 | D30: 01-0F020-0256769 | E30: 2 | F30: 20100070970 | G30: CP02 | H30: C1 | L30: RBT-INVERSION PUBLICITARIA.-RECONOCIMIENTO COSTO - 349669 JUNIO 2026 | M30: 2 | P30: 1030210001 | Q30: 1198069.3 | R30: C1 | S30: No aceptada | T30: RBT-INVERSION PUBLICITARIA.-RECONOCIMIENTO COSTO - 349669 JUNIO 2026
A31: =+A30+1 | B31: 30.06.2026 | C31: 02.07.2026 308874024 | D31: 01-0F020-0256764 | E31: 2 | F31: 20100070970 | G31: CP02 | H31: C1 | L31: RBT-INVERSION PUBLICITARIA.-RESULTADOS MUESTREO ABRIL 2026 | M31: 2 | N31: 6592100001 | O31: =+_xlfn.XLOOKUP(N31,Hoja2!B:B,Hoja2!C:C,,0) | P31: 1030210001 | Q31: 522170.06 | R31: C1 | T31: RBT-INVERSION PUBLICITARIA.-RESULTADOS MUESTREO ABRIL 2026
A32: =+A31+1 | B32: 30.06.2026 | C32: 02.07.2026 308874149 | D32: 01-0F020-0256762 | E32: 2 | F32: 20100070970 | G32: CP02 | H32: C1 | L32: RBT-INVERSION PUBLICITARIA.-RESULTADO MUESTRO MAYO 2026 | M32: 2 | N32: 6592100001 | O32: =+_xlfn.XLOOKUP(N32,Hoja2!B:B,Hoja2!C:C,,0) | P32: 1030210001 | Q32: 563093.64 | R32: C1 | T32: RBT-INVERSION PUBLICITARIA.-RESULTADO MUESTRO MAYO 2026
A33: =+A32+1 | B33: 30.06.2026 | C33: 18.08.2026 313050681 | D33: 01-0F300-0000674 | E33: 2 | F33: 20563468646 | G33: CP02 | H33: C1 | L33: RBT-NO DEVOLUCION JUNIO 2026 | M33: 2 | N33: 6371100005 | O33: =+_xlfn.XLOOKUP(N33,Hoja2!B:B,Hoja2!C:C,,0) | P33: 1030210016 | Q33: 1483.56 | R33: C1 | T33: RBT-NO DEVOLUCION JUNIO 2026
A34: =+A33+1 | B34: 30.06.2026 | C34: 18.08.2026 313050690 | D34: 01-0F300-0000599 | E34: 2 | F34: 20563468646 | G34: CP02 | H34: C1 | L34: RBT-REBATE JUNIO 2026 | M34: 2 | N34: 6371100003 | O34: =+_xlfn.XLOOKUP(N34,Hoja2!B:B,Hoja2!C:C,,0) | P34: 1030210016 | Q34: 1483.56 | R34: C1 | T34: RBT-REBATE JUNIO 2026
A35: =+A34+1 | B35: 06.07.2026 | C35: 10.07.2026 310157610 | D35: 01-0FA39-0026490 | E35: 2 | F35: 20109072177 | G35: CP02 | H35: C1 | L35: RBT-PROMOCIONES DIVERSAS - M001 JUNIO 2026 | M35: 2 | N35: 6371100002 | O35: =+_xlfn.XLOOKUP(N35,Hoja2!B:B,Hoja2!C:C,,0) | P35: 1030210005 | Q35: 10716.24 | R35: C1 | T35: RBT-PROMOCIONES DIVERSAS - M001 JUNIO 2026
A36: =+A35+1 | B36: 06.07.2026 | C36: 10.07.2026 310157607 | D36: 01-0FA39-0026492 | E36: 2 | F36: 20109072177 | G36: CP02 | H36: C1 | L36: RBT-PROMOCIONES DIVERSAS - M001 JUNIO 2026 | M36: 2 | N36: 6371100002 | O36: =+_xlfn.XLOOKUP(N36,Hoja2!B:B,Hoja2!C:C,,0) | P36: 1030210005 | Q36: 1587.69 | R36: C1 | T36: RBT-PROMOCIONES DIVERSAS - M001 JUNIO 2026
A37: =+A36+1 | B37: 06.07.2026 | C37: 10.07.2026 310157598 | D37: 01-0FA38-0663856 | E37: 2 | F37: 20109072177 | G37: CP02 | H37: C1 | L37: RBT-PROMOCIONES DIVERSAS - M001 JUNIO 2026 | M37: 2 | N37: 6371100002 | O37: =+_xlfn.XLOOKUP(N37,Hoja2!B:B,Hoja2!C:C,,0) | P37: 1030210005 | Q37: 9279.57 | R37: C1 | T37: RBT-PROMOCIONES DIVERSAS - M001 JUNIO 2026
A38: =+A37+1 | B38: 06.07.2026 | C38: 10.07.2026 310157600 | D38: 01-0FA38-0663857 | E38: 2 | F38: 20109072177 | G38: CP02 | H38: C1 | L38: RBT-PROMOCIONES DIVERSAS - M001 JUNIO 2026 | M38: 2 | N38: 6371100002 | O38: =+_xlfn.XLOOKUP(N38,Hoja2!B:B,Hoja2!C:C,,0) | P38: 1030210005 | Q38: 1196.52 | R38: C1 | T38: RBT-PROMOCIONES DIVERSAS - M001 JUNIO 2026
A39: =+A38+1 | B39: 05.07.2026 | C39: 07.07.2026 309717925 | D39: 01-0FA38-0663755 | E39: 2 | F39: 20109072177 | G39: CP02 | H39: C1 | L39: RBT-DESARROLLO COMERCIAL - M001 Periodo del 01.07.2026 al 05.07.2026 | M39: 2 | N39: 6371100002 | O39: =+_xlfn.XLOOKUP(N39,Hoja2!B:B,Hoja2!C:C,,0) | P39: 1030210005 | Q39: 38085.29 | R39: C1 | T39: RBT-DESARROLLO COMERCIAL - M001 Periodo del 01.07.2026 al 05.07.2026
A40: =+A39+1 | B40: 08.07.2026 | C40: 22.07.2026 310747871 | D40: 01-0FF32-0539598 | E40: 2 | F40: 20508565934 | G40: CP02 | H40: C1 | L40: RBT-RAPPEL FIJO JUNIO 2026 | M40: 2 | N40: 6371100003 | O40: =+_xlfn.XLOOKUP(N40,Hoja2!B:B,Hoja2!C:C,,0) | P40: 1030210003 | Q40: 161820.29 | R40: C1 | T40: RBT-RAPPEL FIJO JUNIO 2026
A41: =+A40+1 | B41: 15.06.2026 | C41: 07.07.2026 309684354 | D41: 01-0E001-0001081 | E41: 2 | F41: 20612232203 | G41: CP02 | H41: C1 | L41: RBT-PROMOCIONAL HUEVO MAYO 2026 | M41: 2 | N41: 6371100003 | O41: GASTOS DE PROMOCION Y PUBLICIDAD-REBATE FIJO (FIJO) | P41: 1030210019 | Q41: 45764.28 | R41: C1 | T41: RBT-PROMOCIONAL HUEVO MAYO 2026
A42: =+A41+1 | B42: 08.07.2026 | C42: 22.07.2026 310747708 | D42: 01-0FF32-0539492 | E42: 2 | F42: 20508565934 | G42: CP02 | H42: C1 | L42: RBT-SO CROSS LA CALERA MANTEQUILLA LAIVE HS JUNIO 2026 | M42: 2 | N42: 6371100002 | O42: =+_xlfn.XLOOKUP(N42,Hoja2!B:B,Hoja2!C:C,,0) | P42: 1030210003 | Q42: 1767.84 | R42: C1 | T42: RBT-SO CROSS LA CALERA MANTEQUILLA LAIVE HS JUNIO 2026
A43: =+A42+1 | B43: 08.07.2026 | C43: 22.07.2026 310747275 | D43: 01-0FF32-0539440 | E43: 2 | F43: 20508565934 | G43: CP02 | H43: C1 | L43: RBT-SO CROSS LA CALERA DON VITTORIO HS11 JUNIO 2026 | M43: 2 | N43: 6371100002 | O43: =+_xlfn.XLOOKUP(N43,Hoja2!B:B,Hoja2!C:C,,0) | P43: 1030210003 | Q43: 1616.69 | R43: C1 | T43: RBT-SO CROSS LA CALERA DON VITTORIO HS11 JUNIO 2026
A44: =+A43+1 | B44: 08.07.2026 | C44: 22.07.2026 310747365 | D44: 01-0FF32-0539448 | E44: 2 | F44: 20508565934 | G44: CP02 | H44: C1 | L44: RBT-REV VAR LA CALERA 2DO TRIM JUNIO 2026 | M44: 2 | N44: 6371100004 | O44: =+_xlfn.XLOOKUP(N44,Hoja2!B:B,Hoja2!C:C,,0) | P44: 1030210003 | Q44: 85789.21 | R44: C1 | T44: RBT-REV VAR LA CALERA 2DO TRIM JUNIO 2026
A45: =+A44+1 | B45: 08.07.2026 | C45: 22.07.2026 310747164 | D45: 01-0FF32-0539426 | E45: 2 | F45: 20508565934 | G45: CP02 | H45: C1 | L45: RBT-SO PROM PROVINCIA LA CALERA X 30 2026 JUNIO 2026 | M45: 2 | N45: 6371100002 | O45: =+_xlfn.XLOOKUP(N45,Hoja2!B:B,Hoja2!C:C,,0) | P45: 1030210003 | Q45: 6847.3 | R45: C1 | T45: RBT-SO PROM PROVINCIA LA CALERA X 30 2026 JUNIO 2026
A46: =+A45+1 | B46: 08.07.2026 | C46: 22.07.2026 310747157 | D46: 01-0FF32-0539325 | E46: 2 | F46: 20508565934 | G46: CP02 | H46: C1 | L46: RBT-SO CROSS LA CALERA ACEITE HS12 JUNIO 2026 | M46: 2 | N46: 6371100002 | O46: =+_xlfn.XLOOKUP(N46,Hoja2!B:B,Hoja2!C:C,,0) | P46: 1030210003 | Q46: 8092.86 | R46: C1 | T46: RBT-SO CROSS LA CALERA ACEITE HS12 JUNIO 2026
A47: =+A46+1 | B47: 08.07.2026 | C47: 22.07.2026 310747807 | D47: 01-0FF32-0539306 | E47: 2 | F47: 20508565934 | G47: CP02 | H47: C1 | L47: RBT-SO 2DOX50 LUNES HUEVOS 2026 JUNIO 2026 | M47: 2 | N47: 6371100002 | O47: =+_xlfn.XLOOKUP(N47,Hoja2!B:B,Hoja2!C:C,,0) | P47: 1030210003 | Q47: 1871.23 | R47: C1 | T47: RBT-SO 2DOX50 LUNES HUEVOS 2026 JUNIO 2026
A48: =+A47+1 | B48: 08.07.2026 | C48: 22.07.2026 310747483 | D48: 01-0FF32-0539267 | E48: 2 | F48: 20508565934 | G48: CP02 | H48: C1 | L48: RBT-SO T25 HUEVOS X 15 2026 JUNIO 2026 | M48: 2 | N48: 6371100002 | O48: =+_xlfn.XLOOKUP(N48,Hoja2!B:B,Hoja2!C:C,,0) | P48: 1030210003 | Q48: 3743.57 | R48: C1 | T48: RBT-SO T25 HUEVOS X 15 2026 JUNIO 2026
A49: =+A48+1 | B49: 08.07.2026 | C49: 22.07.2026 310747167 | D49: 01-0FF32-0538927 | E49: 2 | F49: 20508565934 | G49: CP02 | H49: C1 | L49: RBT-SO HS13A LA CALERA 2026 JUNIO | M49: 2 | N49: 6371100002 | O49: =+_xlfn.XLOOKUP(N49,Hoja2!B:B,Hoja2!C:C,,0) | P49: 1030210003 | Q49: 23024.66 | R49: C1 | T49: RBT-SO HS13A LA CALERA 2026 JUNIO
...

Sheet Hoja2
B4: CUENTA CONTABLE | C4: TEXTO EXPLICATIVO | D4: COMERCIAL
B5: 6371100003 | C5: GASTOS DE PROMOCION Y PUBLICIDAD-REBATE FIJO (FIJO) | D5: REBATE FIJO
B6: 6371100004 | C6: GASTOS DE PROMOCION Y PUBLICIDAD-REBATE(VARIABLE) | D6: REBATE VARIABLE
B7: 6371100002 | C7: GASTOS DE PROMOCION Y PUBLICIDAD EN SUPERMERCADOS | D7: PROMOCIONES SELL OUT
B8: 6371100022 | C8: GASTOS DE FONDOS PROMOCIONALE EN SUPERMERCADOS | D8: FONDO PROMOCIONAL
B9: 6371100006 | C9: SERV B2B COMERCIAL | D9: SERVICIO B2B COMERCIAL
B10: 6371100005 | C10: GASTOS POR DEVOLUCIÓN DE MERCADERÍA | D10: RECONOCIMIENTO DE STOCK
B11: 6371100007 | C11: SERV DE CALIDAD | D11: SERVICIOS DE CALIDAD
B12: 6371100008 | C12: PENALIDAD DE SERVICIO | D12: PENALIDAD POR NIVEL DE SERVICIO
B13: 6371100009 | C13: PAGO APERTURA DE TIENDA | D13: PAGO APERTURA DE TIENDA
B14: 6592100001 | C14: SANCIONES ADMINISTRATIVAS | D14: DIFERENCIA DE PESOS

Sheet AQP SEM34
A1: ID CABC(1) | B1: Fecha Doc | C1: Texto Cab Doc | D1: REFERENCIA | E1: ID POSC(2)Acreedor | F1: RUC | G1: Cond Pago | H1: Ind Impto | I1: Tipo Detr | J1: Ind Detra | K1: Asignación | L1: Texto Posición | M1: ID POSC(2) Cuenta GASTO | N1: Cuenta Gasto | O1: DETALLE | P1: Centro Costo | Q1: Importe MD | R1: Ind Impto | S1: Asignación | T1: Texto Posición
A2: 1 | B2: 26.08.2026 | D2: 02-0E001-0000160 | E2: 2 | F2: 10295529232 | G2: CP02 | H2: C0 | L2: SERVICIO DE LIMPIEZA SEMANA 34 | M2: 2 | Q2: 195 | R2: C0 | T2: 430060343
A3: 2 | B3: 26.08.2026 | D3: 02-0E001-0000137 | E3: 2 | F3: 10422206855 | G3: CP02 | H3: C0 | L3: SERVICIO DE SANEO SEMANA 34 | M3: 2 | Q3: 420 | R3: C0 | T3: 430060344
A4: 3 | B4: 26.08.2026 | D4: 02-0E001-0000139 | E4: 2 | F4: 10422206855 | G4: CP02 | H4: C0 | L4: SERVICIO DE SANEO SEMANA 34 | M4: 2 | Q4: 60 | R4: C0 | T4: 430060345
A5: 4 | B5: 26.08.2026 | D5: 02-0E001-0000080 | E5: 2 | F5: 10433475882 | G5: CP02 | H5: C0 | L5: SERVICIO DE SANEO SEMANA 34 | M5: 2 | Q5: 240 | R5: C0 | T5: 430060346
A6: 5 | B6: 26.08.2026 | D6: 02-0E001-0000081 | E6: 2 | F6: 10433475882 | G6: CP02 | H6: C0 | L6: SERVICIO DE SANEO SEMANA 34 | M6: 2 | Q6: 300 | R6: C0 | T6: 430060347
A7: 6 | B7: 26.08.2026 | D7: 02-0E001-0000024 | E7: 2 | F7: 10455371053 | G7: CP02 | H7: C0 | L7: SERVICIO DE SANEO SEMANA 34 | M7: 2 | Q7: 300 | R7: C0 | T7: 430060348
A8: 7 | B8: 26.08.2026 | D8: 02-0E001-0000050 | E8: 2 | F8: 10721634081 | G8: CP02 | H8: C0 | L8: SERVICIO DE ESTIBA SEMANA 34 | M8: 2 | Q8: 120 | R8: C0 | T8: 430060349
A9: 8 | B9: 26.08.2026 | D9: 02-0E001-0000051 | E9: 2 | F9: 10721634081 | G9: CP02 | H9: C0 | L9: SERVICIO DE ESTIBA SEMANA 34 | M9: 2 | Q9: 300 | R9: C0 | T9: 430060350
A10: 9 | B10: 26.08.2026 | D10: 02-0E001-0000052 | E10: 2 | F10: 10721634081 | G10: CP02 | H10: C0 | L10: SERVICIO DE ESTIBA SEMANA 34 | M10: 2 | Q10: 160 | R10: C0 | T10: 430060351
A11: 10 | B11: 26.08.2026 | D11: 02-0E001-0000119 | E11: 2 | F11: 10296553153 | G11: CP02 | H11: C0 | L11: SERVICIO DE ESTIBA SEMANA 34 | M11: 2 | Q11: 60 | R11: C0 | T11: 430060352
